Workbook

Sheet Main Data
A1: Battery_ID | B1: Charging_Method | C1: Capacity_Retention | D1: Cycle_Life | E1: Charging_Current | F1: Operating_Temperature | G1: Discharge_Rate | H1: Internal_Resistance
A2: 1 | B2: Fast | C2: 83.318573 | D2: 497.85427 | E2: 6.2220368 | F2: 41.957657 | G2: 3.3595502 | H2: 17.53704
A3: 2 | B3: Fast | C3: 84.309468 | D3: 497.74193 | E3: 2.9179591 | F3: 42.626058 | G3: -0.77253048 | H3: 19.078228
A4: 3 | B4: Fast | C4: 89.676125 | D4: 497.18438 | E4: 2.900009 | F4: 45.898781 | G4: 4.054574 | H4: 17.293706
A5: 4 | B5: Fast | C5: 85.211525 | D5: 496.84246 | E5: -1.5482029 | F5: 49.917156 | G5: -0.74378991 | H5: 21.881206
A6: 5 | B6: Fast | C6: 85.387863 | D6: 498.68852 | E6: 5.371156 | F6: 48.253851 | G6: 3.3907195 | H6: 23.361065
A7: 6 | B7: Fast | C7: 90.145195 | D7: 500.99354 | E7: 2.3677975 | F7: 43.126298 | G7: 4.7899849 | H7: 26.381641
A8: 7 | B8: Fast | C8: 86.382749 | D8: 493.95737 | E8: 1.0297712 | F8: 47.477769 | G8: -1.4653288 | H8: 21.098343
A9: 8 | B9: Fast | C9: 81.204816 | D9: 500.63594 | E9: -1.2360774 | F9: 44.854295 | G9: 4.8239851 | H9: 17.375656
A10: 9 | B10: Fast | C10: 82.939441 | D10: 503.71003 | E10: 2.1007125 | F10: 45.903941 | G10: 0.031401386 | H10: 23.073425
A11: 10 | B11: Fast | C11: 83.663014 | D11: 506.11272 | E11: 0.45281659 | F11: 45.781084 | G11: 2.3830602 | H11: 22.714277
A12: 11 | B12: Fast | C12: 88.672245 | D12: 503.90353 | E12: 1.8089084 | F12: 52.726349 | G12: 2.1055124 | H12: 19.285254
A13: 12 | B13: Fast | C13: 86.079441 | D13: 502.27032 | E13: -0.65279996 | F13: 41.444134 | G13: 0.21841084 | H13: 15.326435
... A301: 300 | B301: Slow | C301: 95.749744 | D301: 1005.5797 | E301: 2.2305982 | F301: 31.118735 | G301: 0.51061303 | H301: 8.9065065

Sheet IF
A1: Capacity_Retention | B1: Status | C1: IF: Apakah kapasitas baterai bagus? | H1: Capacity_Retention | I1: Status | K1: IFS: Kategori performa baterai
A2: 83.318573 | B2: =IF(A2>80,"Bagus", "Kurang") -> Bagus | H2: 83.318573 | I2: {=_xlfn.IFS(H2>90,"Sangat Bagus",H2>80,"Bagus",H2>65,"Cukup Bagus",TRUE,"Kurang")} -> Bagus
A3: 84.309468 | B3: =IF(A3>80,"Bagus", "Kurang") -> Bagus | H3: 84.309468 | I3: {=_xlfn.IFS(H3>90,"Sangat Bagus",H3>80,"Bagus",H3>65,"Cukup Bagus",TRUE,"Kurang")} -> Bagus
A4: 89.676125 | B4: =IF(A4>80,"Bagus", "Kurang") -> Bagus | H4: 89.676125 | I4: {=_xlfn.IFS(H4>90,"Sangat Bagus",H4>80,"Bagus",H4>65,"Cukup Bagus",TRUE,"Kurang")} -> Bagus
A5: 85.211525 | B5: =IF(A5>80,"Bagus", "Kurang") -> Bagus | H5: 85.211525 | I5: {=_xlfn.IFS(H5>90,"Sangat Bagus",H5>80,"Bagus",H5>65,"Cukup Bagus",TRUE,"Kurang")} -> Bagus
A6: 85.387863 | B6: =IF(A6>80,"Bagus", "Kurang") -> Bagus | H6: 85.387863 | I6: {=_xlfn.IFS(H6>90,"Sangat Bagus",H6>80,"Bagus",H6>65,"Cukup Bagus",TRUE,"Kurang")} -> Bagus
A7: 90.145195 | B7: =IF(A7>80,"Bagus", "Kurang") -> Bagus | H7: 90.145195 | I7: {=_xlfn.IFS(H7>90,"Sangat Bagus",H7>80,"Bagus",H7>65,"Cukup Bagus",TRUE,"Kurang")} -> Sangat Bagus
A8: 86.382749 | B8: =IF(A8>80,"Bagus", "Kurang") -> Bagus | H8: 86.382749 | I8: {=_xlfn.IFS(H8>90,"Sangat Bagus",H8>80,"Bagus",H8>65,"Cukup Bagus",TRUE,"Kurang")} -> Bagus
A9: 81.204816 | B9: =IF(A9>80,"Bagus", "Kurang") -> Bagus | H9: 81.204816 | I9: {=_xlfn.IFS(H9>90,"Sangat Bagus",H9>80,"Bagus",H9>65,"Cukup Bagus",TRUE,"Kurang")} -> Bagus
A10: 82.939441 | B10: =IF(A10>80,"Bagus", "Kurang") -> Bagus | H10: 82.939441 | I10: {=_xlfn.IFS(H10>90,"Sangat Bagus",H10>80,"Bagus",H10>65,"Cukup Bagus",TRUE,"Kurang")} -> Bagus
A11: 83.663014 | B11: =IF(A11>80,"Bagus", "Kurang") -> Bagus | H11: 83.663014 | I11: {=_xlfn.IFS(H11>90,"Sangat Bagus",H11>80,"Bagus",H11>65,"Cukup Bagus",TRUE,"Kurang")} -> Bagus
A12: 88.672245 | B12: =IF(A12>80,"Bagus", "Kurang") -> Bagus | H12: 88.672245 | I12: {=_xlfn.IFS(H12>90,"Sangat Bagus",H12>80,"Bagus",H12>65,"Cukup Bagus",TRUE,"Kurang")} -> Bagus
A13: 86.079441 | B13: =IF(A13>80,"Bagus", "Kurang") -> Bagus | H13: 86.079441 | I13: {=_xlfn.IFS(H13>90,"Sangat Bagus",H13>80,"Bagus",H13>65,"Cukup Bagus",TRUE,"Kurang")} -> Bagus
... A301: 95.749744 | B301: =IF(A301>80,"Bagus", "Kurang") -> Bagus | H301: 95.749744 | I301: {=_xlfn.IFS(H301>90,"Sangat Bagus",H301>80,"Bagus",H301>65,"Cukup Bagus",TRUE,"Kurang")} -> Sangat Bagus

Sheet SUM & AVERAGE
A1: Metode | B1: Capacity_Retention | C1: Cycle_Life | D1: Charging_Current | F1: Metode | G1: Capacity_Retention | H1: Cycle_Life | I1: Charging_Current
A2: Fast | B2: =SUMIF(F2:F301,A2,G2:G301) -> 8527.1218 | C2: =SUMIF($F$2:F301,Table4[[#This Row],[Metode]],$H$2:H301) -> 49989.133 | D2: =SUMIF($F$2:F301,Table4[[#This Row],[Metode]],$I$2:I301) -> 255.10676 | F2: Fast | G2: 83.318573 | H2: 497.85427 | I2: 6.2220368
A3: Normal | B3: =SUMIF(F3:F302,A3,G3:G302) -> 8967.736 | C3: =SUMIF($F$2:F302,Table4[[#This Row],[Metode]],$H$2:H302) -> 80031.755 | D3: =SUMIF($F$2:F302,Table4[[#This Row],[Metode]],$I$2:I302) -> 231.76206 | F3: Fast | G3: 84.309468 | H3: 497.74193 | I3: 2.9179591
A4: Slow | B4: =SUMIF(F2:F303,A4,G2:G303) -> 9236.1395 | C4: =SUMIF($F$2:F303,Table4[[#This Row],[Metode]],$H$2:H303) -> 99987.31 | D4: =SUMIF($F$2:F303,Table4[[#This Row],[Metode]],$I$2:I303) -> 178.07691 | F4: Fast | G4: 89.676125 | H4: 497.18438 | I4: 2.900009
F5: Fast | G5: 85.211525 | H5: 496.84246 | I5: -1.5482029
A6: SUMIF – Menjumlahkan dengan Syarat | F6: Fast | G6: 85.387863 | H6: 498.68852 | I6: 5.371156
F7: Fast | G7: 90.145195 | H7: 500.99354 | I7: 2.3677975
F8: Fast | G8: 86.382749 | H8: 493.95737 | I8: 1.0297712
F9: Fast | G9: 81.204816 | H9: 500.63594 | I9: -1.2360774
A10: Column1 | B10: Column2 | C10: Column3 | F10: Fast | G10: 82.939441 | H10: 503.71003 | I10: 2.1007125
A11: Metode | B11: Capacity_Retention | C11: Cycle_Life | F11: Fast | G11: 83.663014 | H11: 506.11272 | I11: 0.45281659
A12: Fast | B12: =AVERAGEIF($F$2:F301,Table6[[#This Row],[Column1]],$G$2:G301) -> 85.271218 | C12: =AVERAGEIF($F$2:F301,Table6[[#This Row],[Column1]],$H$2:H301) -> 499.89133 | F12: Fast | G12: 88.672245 | H12: 503.90353 | I12: 1.8089084
A13: Normal | B13: =AVERAGEIF($F$2:F301,Table6[[#This Row],[Column1]],$G$2:G301) -> 89.67736 | C13: =AVERAGEIF($F$2:F302,Table6[[#This Row],[Column1]],$H$2:H302) -> 800.31755 | F13: Fast | G13: 86.079441 | H13: 502.27032 | I13: -0.65279996
A14: Slow | B14: =AVERAGEIF($F$2:F301,Table6[[#This Row],[Column1]],$G$2:G303) -> 92.361395 | C14: =AVERAGEIF($F$2:F303,Table6[[#This Row],[Column1]],$H$2:H303) -> 999.8731 | F14: Fast | G14: 86.202314 | H14: 494.81981 | I14: 8.0627684
F15: Fast | G15: 85.332048 | H15: 498.19548 | I15: 2.9519924
A16: AVERAGEIF – Merata-ratakan dengan Syarat | F16: Fast | G16: 83.332477 | H16: 498.94386 | I16: 6.2248352
F17: Fast | G17: 90.360739 | H17: 502.11057 | I17: -4.805099
F18: Fast | G18: 86.493551 | H18: 499.68299 | I18: 1.6404065
F19: Fast | G19: 79.100149 | H19: 496.22405 | I19: 0.97355313
F20: Fast | G20: 87.104068 | H20: 505.05331 | I20: -0.66877854
A21: FORECAST – Prediksi Berdasarkan Tren | F21: Fast | G21: 83.581626 | H21: 502.73417 | I21: 7.6398275
A22: =FORECAST(100,G2:G301,H2:H301) -> 79.632232 | F22: Fast | G22: 81.796529 | H22: 500.71229 | I22: -1.2458458
F23: Fast | G23: 84.346075 | H23: 503.65433 | I23: 3.9551708
A24: 100: nilai baru (Cycle Life) yang ingin diprediksi | F24: Fast | G24: 81.921987 | H24: 495.98368 | I24: 5.5393089
F25: Fast | G25: 82.813326 | H25: 501.98246 | I25: 3.5345706
A26: G2:G301: nilai yang diprediksi (Capacity Retention) | F26: Fast | G26: 83.124882 | H26: 498.43126 | I26: 0.37423357
F27: Fast | G27: 79.93992 | H27: 502.05124 | I27: 5.8234974
A28: H2:H301: nilai historis (Cycle Life) | F28: Fast | G28: 87.513361 | H28: 499.81753 | I28: 3.5117642
F29: Fast | G29: 85.460119 | H29: 501.89888 | I29: -0.19049372
A30: Cocok untuk: | F30: Fast | G30: 81.585589 | H30: 504.00655 | I30: -1.1641471
F31: Fast | G31: 88.761445 | H31: 500.02187 | I31: 9.2601523
F32: Fast | G32: 86.279393 | H32: 503.05268 | I32: 0.96449056
F33: Fast | G33: 84.114786 | H33: 496.4347 | I33: -2.566715
F34: Fast | G34: 87.685377 | H34: 497.83519 | I34: 4.5997781
F35: Fast | G35: 87.6344 | H35: 504.55765 | I35: 3.9306908
F36: Fast | G36: 87.464743 | H36: 501.13216 | I36: -1.061503
F37: Fast | G37: 87.065921 | H37: 493.84333 | I37: -2.8288692
F38: Fast | G38: 86.661753 | H38: 495.90789 | I38: 2.6510924
F39: Fast | G39: 84.814265 | H39: 499.39766 | I39: 6.4181889
F40: Fast | G40: 84.082112 | H40: 502.59734 | I40: 4.9083721
...

Sheet X,VLOOK UP
A1: Battery_ID | B1: Charging_Method | C1: Capacity_Retention | E1: VLOOKUP – Mencari Data Secara Vertikal | N1: Battery Id | O1: capacity | P1: cycle life | Q1: XLOOKUP – Pengganti Modern VLOOKUP
A2: 1 | B2: {=VLOOKUP(A2,'Main Data'!$A$2:$H$301,{2.3},FALSE)} -> Fast | C2: {=VLOOKUP(B2,'Main Data'!$B$2:$I$301,{2.3},FALSE)} -> 83.318573 | N2: 23 | O2: =_xlfn.XLOOKUP(N2,Table1[Battery_ID],Table1[Capacity_Retention],"Tidak Ada") -> 81.921987 | P2: =_xlfn.XLOOKUP(N2,Table1[Battery_ID],Table1[Cycle_Life],"Tidak Ada") -> 495.98368 | R2: Lebih fleksibel dari VLOOKUP
A3: 10 | B3: {=VLOOKUP(A3,'Main Data'!$A$2:$H$301,{2.3},FALSE)} -> Fast | C3: {=VLOOKUP(B3,'Main Data'!$B$2:$I$301,{2.3},FALSE)} -> 83.318573 | E3: ✅ Cari Cycle Life berdasarkan Battery ID | N3: 118 | O3: =_xlfn.XLOOKUP(N3,Table1[Battery_ID],Table1[Capacity_Retention],"Tidak Ada") -> 88.077882 | P3: =_xlfn.XLOOKUP(N3,Table1[Battery_ID],Table1[Cycle_Life],"Tidak Ada") -> 801.29085
A4: 167 | B4: {=VLOOKUP(A4,'Main Data'!$A$2:$H$301,{2.3},FALSE)} -> Normal | C4: {=VLOOKUP(B4,'Main Data'!$B$2:$I$301,{2.3},FALSE)} -> 87.86878 | N4: 333 | O4: =_xlfn.XLOOKUP(N4,Table1[Battery_ID],Table1[Capacity_Retention],"Tidak Ada") -> Tidak Ada | P4: =_xlfn.XLOOKUP(N4,Table1[Battery_ID],Table1[Cycle_Life],"Tidak Ada") -> Tidak Ada | R4: Bisa cari dari kanan ke kiri, dan tidak perlu hitung posisi kolom
A5: 200 | B5: {=VLOOKUP(A5,'Main Data'!$A$2:$H$301,{2.3},FALSE)} -> Normal | C5: {=VLOOKUP(B5,'Main Data'!$B$2:$I$301,{2.3},FALSE)} -> 87.86878 | N5: 290 | O5: =_xlfn.XLOOKUP(N5,Table1[Battery_ID],Table1[Capacity_Retention],"Tidak Ada") -> 92.504196 | P5: =_xlfn.XLOOKUP(N5,Table1[Battery_ID],Table1[Cycle_Life],"Tidak Ada") -> 996.05047
A6: 300 | B6: {=VLOOKUP(A6,'Main Data'!$A$2:$H$301,{2.3},FALSE)} -> Slow | C6: {=VLOOKUP(B6,'Main Data'!$B$2:$I$301,{2.3},FALSE)} -> 98.596431 | N6: 1 | O6: =_xlfn.XLOOKUP(N6,Table1[Battery_ID],Table1[Capacity_Retention],"Tidak Ada") -> 83.318573 | P6: =_xlfn.XLOOKUP(N6,Table1[Battery_ID],Table1[Cycle_Life],"Tidak Ada") -> 497.85427
A7: 234 | B7: {=VLOOKUP(A7,'Main Data'!$A$2:$H$301,{2.3},FALSE)} -> Slow | C7: {=VLOOKUP(B7,'Main Data'!$B$2:$I$301,{2.3},FALSE)} -> 98.596431 | E7: B2: nilai yang dicari (Battery ID)
E9: Main Data B2:I301: area data | N9: Charging Method | O9: Capacity | P9: Temprature | Q9: Cycle life
N10: Fast | O10: 83.318573 | P10: 41.957657 | Q10: {=_xlfn.XLOOKUP(1, (Table1[Charging_Method]=Table1421[[#This Row],[Charging Method]]) * (Table1[Capacity_Retention]=Table1421[[#This Row],[Capacity]]) * (Table1[Operating_Temperature]=Table1421[[#This Row],[Temprature]]), Table1[Cycle_Life])} -> 497.85427
E11: {2;3}: ambil dari kolom ke-2&3 (Cycle Life) | N11: Fast | O11: 84.309468 | P11: 42.626058 | Q11: {=_xlfn.XLOOKUP(1, (Table1[Charging_Method]=Table1421[[#This Row],[Charging Method]]) * (Table1[Capacity_Retention]=Table1421[[#This Row],[Capacity]]) * (Table1[Operating_Temperature]=Table1421[[#This Row],[Temprature]]), Table1[Cycle_Life])} -> 497.74193
N12: Fast | O12: 89.676125 | P12: 45.898781 | Q12: {=_xlfn.XLOOKUP(1, (Table1[Charging_Method]=Table1421[[#This Row],[Charging Method]]) * (Table1[Capacity_Retention]=Table1421[[#This Row],[Capacity]]) * (Table1[Operating_Temperature]=Table1421[[#This Row],[Temprature]]), Table1[Cycle_Life])} -> 497.18438
E13: FALSE: pencocokan eksak | N13: Fast | O13: 85.211525 | P13: 49.917156 | Q13: {=_xlfn.XLOOKUP(1, (Table1[Charging_Method]=Table1421[[#This Row],[Charging Method]]) * (Table1[Capacity_Retention]=Table1421[[#This Row],[Capacity]]) * (Table1[Operating_Temperature]=Table1421[[#This Row],[Temprature]]), Table1[Cycle_Life])} -> 496.84246
N14: Normal | O14: 88.166502 | P14: 36.452298 | Q14: {=_xlfn.XLOOKUP(1, (Table1[Charging_Method]=Table1421[[#This Row],[Charging Method]]) * (Table1[Capacity_Retention]=Table1421[[#This Row],[Capacity]]) * (Table1[Operating_Temperature]=Table1421[[#This Row],[Temprature]]), Table1[Cycle_Life])} -> 801.09234
N15: Normal | O15: 86.44356 | P15: 34.265349 | Q15: {=_xlfn.XLOOKUP(1, (Table1[Charging_Method]=Table1421[[#This Row],[Charging Method]]) * (Table1[Capacity_Retention]=Table1421[[#This Row],[Capacity]]) * (Table1[Operating_Temperature]=Table1421[[#This Row],[Temprature]]), Table1[Cycle_Life])} -> 801.65647
N16: Slow | O16: 98.596431 | P16: 32.747976 | Q16: {=_xlfn.XLOOKUP(1, (Table1[Charging_Method]=Table1421[[#This Row],[Charging Method]]) * (Table1[Capacity_Retention]=Table1421[[#This Row],[Capacity]]) * (Table1[Operating_Temperature]=Table1421[[#This Row],[Temprature]]), Table1[Cycle_Life])} -> 998.19432
N17: Slow | O17: 95.937239 | P17: 32.401867 | Q17: {=_xlfn.XLOOKUP(1, (Table1[Charging_Method]=Table1421[[#This Row],[Charging Method]]) * (Table1[Capacity_Retention]=Table1421[[#This Row],[Capacity]]) * (Table1[Operating_Temperature]=Table1421[[#This Row],[Temprature]]), Table1[Cycle_Life])} -> 997.0189
N18: Slow | O18: 91.204565 | P18: 27.190293 | Q18: {=_xlfn.XLOOKUP(1, (Table1[Charging_Method]=Table1421[[#This Row],[Charging Method]]) * (Table1[Capacity_Retention]=Table1421[[#This Row],[Capacity]]) * (Table1[Operating_Temperature]=Table1421[[#This Row],[Temprature]]), Table1[Cycle_Life])} -> 1003.0804

Sheet FILTER,INDEX & MATCH
A1: Charging Method | B1: Capacity | C1: Temprature | D1: Cycle life | F1: Fungsi FILTER di Excel digunakan untuk menyaring data berdasarkan kriteria tertentu.
A2: Fast | B2: 83.318573 | C2: 41.957657 | D2: {=_xlfn._xlws.FILTER( Table1[Cycle_Life], (Table1[Charging_Method]=Table14[[#This Row],[Charging Method]]) * (Table1[Capacity_Retention]=Table14[[#This Row],[Capacity]]) * (Table1[Operating_Temperature]=Table14[[#This Row],[Temprature]]) )} -> 497.85427 | F2: FILTER(range_data; kondisi)
A3: Fast | B3: 84.309468 | C3: 42.626058 | D3: {=_xlfn._xlws.FILTER( Table1[Cycle_Life], (Table1[Charging_Method]=Table14[[#This Row],[Charging Method]]) * (Table1[Capacity_Retention]=Table14[[#This Row],[Capacity]]) * (Table1[Operating_Temperature]=Table14[[#This Row],[Temprature]]) )} -> 497.74193 | F3: range_data: data yang mau ditampilkan.
A4: Fast | B4: 89.676125 | C4: 45.898781 | D4: {=_xlfn._xlws.FILTER( Table1[Cycle_Life], (Table1[Charging_Method]=Table14[[#This Row],[Charging Method]]) * (Table1[Capacity_Retention]=Table14[[#This Row],[Capacity]]) * (Table1[Operating_Temperature]=Table14[[#This Row],[Temprature]]) )} -> 497.18438 | F4: kondisi: syarat penyaringannya.
A5: Fast | B5: 85.211525 | C5: 49.917156 | D5: {=_xlfn._xlws.FILTER( Table1[Cycle_Life], (Table1[Charging_Method]=Table14[[#This Row],[Charging Method]]) * (Table1[Capacity_Retention]=Table14[[#This Row],[Capacity]]) * (Table1[Operating_Temperature]=Table14[[#This Row],[Temprature]]) )} -> 496.84246
A6: Normal | B6: 88.166502 | C6: 36.452298 | D6: {=_xlfn._xlws.FILTER( Table1[Cycle_Life], (Table1[Charging_Method]=Table14[[#This Row],[Charging Method]]) * (Table1[Capacity_Retention]=Table14[[#This Row],[Capacity]]) * (Table1[Operating_Temperature]=Table14[[#This Row],[Temprature]]) )} -> 801.09234
A7: Normal | B7: 86.44356 | C7: 34.265349 | D7: {=_xlfn._xlws.FILTER( Table1[Cycle_Life], (Table1[Charging_Method]=Table14[[#This Row],[Charging Method]]) * (Table1[Capacity_Retention]=Table14[[#This Row],[Capacity]]) * (Table1[Operating_Temperature]=Table14[[#This Row],[Temprature]]) )} -> 801.65647
A8: Slow | B8: 98.596431 | C8: 32.747976 | D8: {=_xlfn._xlws.FILTER( Table1[Cycle_Life], (Table1[Charging_Method]=Table14[[#This Row],[Charging Method]]) * (Table1[Capacity_Retention]=Table14[[#This Row],[Capacity]]) * (Table1[Operating_Temperature]=Table14[[#This Row],[Temprature]]) )} -> 998.19432
A9: Slow | B9: 95.937239 | C9: 32.401867 | D9: {=_xlfn._xlws.FILTER( Table1[Cycle_Life], (Table1[Charging_Method]=Table14[[#This Row],[Charging Method]]) * (Table1[Capacity_Retention]=Table14[[#This Row],[Capacity]]) * (Table1[Operating_Temperature]=Table14[[#This Row],[Temprature]]) )} -> 997.0189
A10: Slow | B10: 91.204565 | C10: 27.190293 | D10: {=_xlfn._xlws.FILTER( Table1[Cycle_Life], (Table1[Charging_Method]=Table14[[#This Row],[Charging Method]]) * (Table1[Capacity_Retention]=Table14[[#This Row],[Capacity]]) * (Table1[Operating_Temperature]=Table14[[#This Row],[Temprature]]) )} -> 1003.0804
A12: Capacity | B12: Methode
A13: 85.211525 | B13: =INDEX(Table1[Charging_Method],MATCH(Table19[[#This Row],[Capacity]],Table1[Capacity_Retention],0)) -> Fast | D13: INDEX + MATCH – Kombinasi dan Fleksibel | L13: MATCH
A14: 88.166502 | B14: =INDEX(Table1[Charging_Method],MATCH(Table19[[#This Row],[Capacity]],Table1[Capacity_Retention],0)) -> Normal | D14: INDEX(D2:D100, MATCH(10, A2:A100, 0))
A15: 92.972913 | B15: =INDEX(Table1[Charging_Method],MATCH(Table19[[#This Row],[Capacity]],Table1[Capacity_Retention],0)) -> Slow | D15: MATCH(10, A2:A100, 0): cari posisi Battery ID = 10 | L15: Mencari posisi dari suatu nilai dalam satu baris atau kolom.
A16: 89.655391 | B16: =INDEX(Table1[Charging_Method],MATCH(Table19[[#This Row],[Capacity]],Table1[Capacity_Retention],0)) -> Slow | D16: INDEX akan ambil nilai dari kolom Cycle_Life sesuai posisi | L16: MATCH(10, A2:A100, 0)
A17: 88.672245 | B17: =INDEX(Table1[Charging_Method],MATCH(Table19[[#This Row],[Capacity]],Table1[Capacity_Retention],0)) -> Fast | D17: Kelebihan: | L17: Cari nilai 10 di kolom A2:A100, dan kasih tahu posisinya (misal: baris ke-5 dalam rentang itu).
D18: Lebih fleksibel dari VLOOKUP
D19: Tidak tergantung urutan kolom | L19: INDEX
L20: Mengambil nilai dari posisi tertentu dalam satu rentang.
L21: INDEX(D2:D100, 5)
L22: Ambil nilai baris ke-5 dari kolom D2:D100.
